Workbook

Sheet Cover
B2: Renna Media x Montclair Digital
B3: Acquisition Integration Model
B5: Version: | C5: v1.0
B6: Date: | C6: 2026-04-27
B7: Prepared for: | C7: Matt Saunders
B9: Sheets
B11: Assumptions | C11: All input drivers. Edit yellow-highlighted cells to flex the model.
B12: Deal_Structure | C12: Purchase price, debt mix, amortization, debt service schedule.
B13: Print_PnL | C13: 5-year print business P&L for Down / Base / Up scenarios.
B14: MD_CrossSell | C14: Montclair Digital cross-sell economics across conversion scenarios.
B15: Combined_Returns | C15: Owner cash flow, cumulative cash, IRR by scenario combination.
B16: Sensitivity | C16: Sensitivity of Year 3 owner cash to purchase price and MD conversion.
B19: Color Conventions
B21: Blue text | C21: Hardcoded inputs. Change these to flex the model.
B22: Black text | C22: Formulas and calculations. Do not edit.
B23: Green text | C23: Cross-sheet references.
B24: Yellow fill | C24: Key driver. Highest sensitivity. Update first.

Sheet Assumptions
B2: Assumptions
B4: DEAL TERMS
B5: Purchase price | C5: 400000 | F5: Target offer; asking is $500K
B6: SBA loan % of price | C6: 0.7 | F6: SBA 7(a) portion of purchase
B7: Seller note % of price | C7: 0.1 | F7: Seller carry; balance is buyer equity
B8: SBA interest rate | C8: 0.115 | F8: Prime + 2.75%, est.
B9: SBA term (years) | C9: 10 | F9: SBA 7(a) goodwill term
B10: Seller note rate | C10: 0.07 | F10: Negotiated down from 8% asked
B11: Seller note term (years) | C11: 3 | F11: Per CIM
B12: Closing costs / fees | C12: 25000 | F12: SBA fees, legal, diligence
B14: PRINT BUSINESS BASELINE (per CIM)
B15: 2025 Revenue | C15: 1060889 | F15: Per CIM tax return
B16: 2025 COGS % | C16: 0.763 | F16: Per CIM
B17: 2025 Adj OpEx (post add-back) | C17: 72669 | F17: Per CIM recasted
B18: 3-yr avg SDE (normalized) | C18: 140043 | F18: Per CIM 3-yr avg
B20: POST-CLOSE OPERATOR + ADJUSTMENTS
B21: Full-time operator base salary | C21: 65000 | F21: Replaces Joe + Tina day-to-day
B22: Operator benefits / payroll tax % | C22: 0.2 | F22: Burdened load
B23: Add-back: social media role restored | C23: 25000 | F23: Part-time; needed for digital push
B24: Owner / Matt time on Renna ($) | C24: 0 | F24: Set non-zero to test self-operate scenario
B26: PRINT SCENARIOS (5-YEAR REVENUE GROWTH)
B27: Scenario | C27: Y1 vs 2025 | D27: Y2-5 CAGR | E27: Steady-state COGS %
B28: Down | C28: -0.2 | D28: -0.05 | E28: 0.79 | F28: Lose 20% of advertisers in Y1, 5% decay after
B29: Base | C29: -0.05 | D29: 0.02 | E29: 0.76 | F29: Modest Y1 churn, stabilize, light growth
B30: Up | C30: 0.05 | D30: 0.08 | E30: 0.74 | F30: Sales engine + pricing + 6 new towns
B32: MONTCLAIR DIGITAL CROSS-SELL
B33: Active Renna advertisers (base) | C33: 120 | F33: Per CIM
B34: Annual MD ARPU per converted advertiser | C34: 12000 | F34: $1K/mo retainer; conservative
B35: MD service gross margin | C35: 0.7 | F35: Service business; primarily labor
B36: MD delivery cost per active client / yr | C36: 3600 | F36: Embedded in 70% margin; informational
B37: Annual churn on MD clients | C37: 0.2 | F37: Industry typical for SMB digital
B38: Conversion ramp Y1 (% of steady-state) | C38: 0.5 | F38: Half of steady conversion in Y1
B39: Conversion ramp Y2 (% of steady-state) | C39: 0.85 | F39: Approaches steady
B40: Conversion ramp Y3+ (% of steady-state) | C40: 1 | F40: Steady-state hit by Y3
B42: MD CONVERSION SCENARIOS (% of advertiser base)
B43: Scenario | C43: Steady-state %
B44: Low | C44: 0.05
B45: Mid | C45: 0.1
B46: High | C46: 0.15
B47: Stretch | C47: 0.2

Sheet Deal_Structure
B2: Deal Structure & Debt Service
B4: SOURCES & USES
B5: USES
B6: Purchase price | C6: =Assumptions!$C$5 -> 400000
B7: Closing costs / fees | C7: =Assumptions!$C$12 -> 25000
B8: Total uses | C8: =SUM(C6:C7) -> 425000
B10: SOURCES
B11: Buyer equity (cash at close) | C11: =C8-C12-C13 -> 105000
B12: SBA 7(a) loan | C12: =Assumptions!$C$5*Assumptions!$C$6 -> 280000
B13: Seller note | C13: =Assumptions!$C$5*Assumptions!$C$7 -> 40000
B14: Total sources | C14: =SUM(C11:C13) -> 425000
B15: Check (Sources - Uses) | C15: =C14-C8 -> 0
B17: ANNUAL DEBT SERVICE
B18: SBA loan annual P&I | C18: =-PMT(Assumptions!$C$8,Assumptions!$C$9,C12) -> 48545.619
B19: Seller note annual P&I | C19: =-PMT(Assumptions!$C$10,Assumptions!$C$11,C13) -> 15242.067
B20: Total Y1-Y3 annual debt service | C20: =C18+C19 -> 63787.685
B21: Total Y4+ annual debt service (seller note paid off) | C21: =C18 -> 48545.619
B23: DEBT SERVICE BY YEAR
B24: Year | C24: Y1 | D24: Y2 | E24: Y3 | F24: Y4 | G24: Y5
B25: SBA debt service | C25: =$C$18 -> 48545.619 | D25: =$C$18 -> 48545.619 | E25: =$C$18 -> 48545.619 | F25: =$C$18 -> 48545.619 | G25: =$C$18 -> 48545.619
B26: Seller note debt service | C26: =$C$19 -> 15242.067 | D26: =$C$19 -> 15242.067 | E26: =$C$19 -> 15242.067 | F26: 0 | G26: 0
B27: Total annual debt service | C27: =SUM(C25:C26) -> 63787.685 | D27: =SUM(D25:D26) -> 63787.685 | E27: =SUM(E25:E26) -> 63787.685 | F27: =SUM(F25:F26) -> 48545.619 | G27: =SUM(G25:G26) -> 48545.619

Sheet Print_PnL
B2: Print Business P&L (5-Year by Scenario)
B3: Y0 = 2025 actual per CIM. Y1-Y5 projected.
B5: SCENARIO: DOWN
C6: Y0 (2025) | D6: Y1 | E6: Y2 | F6: Y3 | G6: Y4 | H6: Y5
B7: Revenue | C7: =Assumptions!$C$15 -> 1060889 | D7: =C7*(1+Assumptions!$C$28) -> 848711.2 | E7: =D7*(1+Assumptions!$D$28) -> 806275.64 | F7: =E7*(1+Assumptions!$D$28) -> 765961.86 | G7: =F7*(1+Assumptions!$D$28) -> 727663.77 | H7: =G7*(1+Assumptions!$D$28) -> 691280.58
B8: COGS | C8: =-C7*Assumptions!$C$16 -> -809458.31 | D8: =-D7*Assumptions!$E$28 -> -670481.85 | E8: =-E7*Assumptions!$E$28 -> -636957.76 | F8: =-F7*Assumptions!$E$28 -> -605109.87 | G8: =-G7*Assumptions!$E$28 -> -574854.37 | H8: =-H7*Assumptions!$E$28 -> -546111.66
B9: Gross profit | C9: =C7+C8 -> 251430.69 | D9: =D7+D8 -> 178229.35 | E9: =E7+E8 -> 169317.88 | F9: =F7+F8 -> 160851.99 | G9: =G7+G8 -> 152809.39 | H9: =H7+H8 -> 145168.92
B10: OpEx (excl. labor) | C10: =-Assumptions!$C$17 -> -72669 | D10: =C10*(1+((D7/C7)-1)*0.5) -> -65402.1 | E10: =D10*(1+((E7/D7)-1)*0.5) -> -63767.048 | F10: =E10*(1+((F7/E7)-1)*0.5) -> -62172.871 | G10: =F10*(1+((G7/F7)-1)*0.5) -> -60618.55 | H10: =G10*(1+((H7/G7)-1)*0.5) -> -59103.086
B11: Labor (operator + social) | C11: 0 | D11: =-((Assumptions!$C$21*(1+Assumptions!$C$22))+Assumptions!$C$23) -> -103000 | E11: =-((Assumptions!$C$21*(1+Assumptions!$C$22))+Assumptions!$C$23) -> -103000 | F11: =-((Assumptions!$C$21*(1+Assumptions!$C$22))+Assumptions!$C$23) -> -103000 | G11: =-((Assumptions!$C$21*(1+Assumptions!$C$22))+Assumptions!$C$23) -> -103000 | H11: =-((Assumptions!$C$21*(1+Assumptions!$C$22))+Assumptions!$C$23) -> -103000
B12: Operating cash flow (post-labor) | C12: =C9+C10+C11 -> 178761.69 | D12: =D9+D10+D11 -> 9827.252 | E12: =E9+E10+E11 -> 2550.8369 | F12: =F9+F10+F11 -> -4320.8811 | G12: =G9+G10+G11 -> -10809.159 | H12: =H9+H10+H11 -> -16934.165
B15: SCENARIO: BASE
C16: Y0 (2025) | D16: Y1 | E16: Y2 | F16: Y3 | G16: Y4 | H16: Y5
B17: Revenue | C17: =Assumptions!$C$15 -> 1060889 | D17: =C17*(1+Assumptions!$C$29) -> 1007844.6 | E17: =D17*(1+Assumptions!$D$29) -> 1028001.4 | F17: =E17*(1+Assumptions!$D$29) -> 1048561.5 | G17: =F17*(1+Assumptions!$D$29) -> 1069532.7 | H17: =G17*(1+Assumptions!$D$29) -> 1090923.4
B18: COGS | C18: =-C17*Assumptions!$C$16 -> -809458.31 | D18: =-D17*Assumptions!$E$29 -> -765961.86 | E18: =-E17*Assumptions!$E$29 -> -781281.1 | F18: =-F17*Assumptions!$E$29 -> -796906.72 | G18: =-G17*Assumptions!$E$29 -> -812844.85 | H18: =-H17*Assumptions!$E$29 -> -829101.75
B19: Gross profit | C19: =C17+C18 -> 251430.69 | D19: =D17+D18 -> 241882.69 | E19: =E17+E18 -> 246720.35 | F19: =F17+F18 -> 251654.75 | G19: =G17+G18 -> 256687.85 | H19: =H17+H18 -> 261821.6
B20: OpEx (excl. labor) | C20: =-Assumptions!$C$17 -> -72669 | D20: =C20*(1+((D17/C17)-1)*0.5) -> -70852.275 | E20: =D20*(1+((E17/D17)-1)*0.5) -> -71560.798 | F20: =E20*(1+((F17/E17)-1)*0.5) -> -72276.406 | G20: =F20*(1+((G17/F17)-1)*0.5) -> -72999.17 | H20: =G20*(1+((H17/G17)-1)*0.5) -> -73729.161
B21: Labor (operator + social) | C21: 0 | D21: =-((Assumptions!$C$21*(1+Assumptions!$C$22))+Assumptions!$C$23) -> -103000 | E21: =-((Assumptions!$C$21*(1+Assumptions!$C$22))+Assumptions!$C$23) -> -103000 | F21: =-((Assumptions!$C$21*(1+Assumptions!$C$22))+Assumptions!$C$23) -> -103000 | G21: =-((Assumptions!$C$21*(1+Assumptions!$C$22))+Assumptions!$C$23) -> -103000 | H21: =-((Assumptions!$C$21*(1+Assumptions!$C$22))+Assumptions!$C$23) -> -103000
B22: Operating cash flow (post-labor) | C22: =C19+C20+C21 -> 178761.69 | D22: =D19+D20+D21 -> 68030.417 | E22: =E19+E20+E21 -> 72159.548 | F22: =F19+F20+F21 -> 76378.347 | G22: =G19+G20+G21 -> 80688.678 | H22: =H19+H20+H21 -> 85092.443
B25: SCENARIO: UP
C26: Y0 (2025) | D26: Y1 | E26: Y2 | F26: Y3 | G26: Y4 | H26: Y5
B27: Revenue | C27: =Assumptions!$C$15 -> 1060889 | D27: =C27*(1+Assumptions!$C$30) -> 1113933.4 | E27: =D27*(1+Assumptions!$D$30) -> 1203048.1 | F27: =E27*(1+Assumptions!$D$30) -> 1299292 | G27: =F27*(1+Assumptions!$D$30) -> 1403235.3 | H27: =G27*(1+Assumptions!$D$30) -> 1515494.2
B28: COGS | C28: =-C27*Assumptions!$C$16 -> -809458.31 | D28: =-D27*Assumptions!$E$30 -> -824310.75 | E28: =-E27*Assumptions!$E$30 -> -890255.61 | F28: =-F27*Assumptions!$E$30 -> -961476.06 | G28: =-G27*Assumptions!$E$30 -> -1038394.1 | H28: =-H27*Assumptions!$E$30 -> -1121465.7
B29: Gross profit | C29: =C27+C28 -> 251430.69 | D29: =D27+D28 -> 289622.7 | E29: =E27+E28 -> 312792.51 | F29: =F27+F28 -> 337815.91 | G29: =G27+G28 -> 364841.19 | H29: =H27+H28 -> 394028.48
B30: OpEx (excl. labor) | C30: =-Assumptions!$C$17 -> -72669 | D30: =C30*(1+((D27/C27)-1)*0.5) -> -74485.725 | E30: =D30*(1+((E27/D27)-1)*0.5) -> -77465.154 | F30: =E30*(1+((F27/E27)-1)*0.5) -> -80563.76 | G30: =F30*(1+((G27/F27)-1)*0.5) -> -83786.311 | H30: =G30*(1+((H27/G27)-1)*0.5) -> -87137.763
B31: Labor (operator + social) | C31: 0 | D31: =-((Assumptions!$C$21*(1+Assumptions!$C$22))+Assumptions!$C$23) -> -103000 | E31: =-((Assumptions!$C$21*(1+Assumptions!$C$22))+Assumptions!$C$23) -> -103000 | F31: =-((Assumptions!$C$21*(1+Assumptions!$C$22))+Assumptions!$C$23) -> -103000 | G31: =-((Assumptions!$C$21*(1+Assumptions!$C$22))+Assumptions!$C$23) -> -103000 | H31: =-((Assumptions!$C$21*(1+Assumptions!$C$22))+Assumptions!$C$23) -> -103000
B32: Operating cash flow (post-labor) | C32: =C29+C30+C31 -> 178761.69 | D32: =D29+D30+D31 -> 112136.97 | E32: =E29+E30+E31 -> 132327.36 | F32: =F29+F30+F31 -> 154252.15 | G32: =G29+G30+G31 -> 178054.88 | H32: =H29+H30+H31 -> 203890.72

Sheet MD_CrossSell
B2: Montclair Digital Cross-Sell Economics
B3: Modeled per conversion scenario. Outputs feed Combined_Returns.
B5: MD CONVERSION: LOW
C6: Y1 | D6: Y2 | E6: Y3 | F6: Y4 | G6: Y5
B7: Steady-state target clients | C7: =Assumptions!$C$33*Assumptions!$C$44 -> 6 | D7: =Assumptions!$C$33*Assumptions!$C$44 -> 6 | E7: =Assumptions!$C$33*Assumptions!$C$44 -> 6 | F7: =Assumptions!$C$33*Assumptions!$C$44 -> 6 | G7: =Assumptions!$C$33*Assumptions!$C$44 -> 6
B8: Active clients (avg over year) | C8: =C7*Assumptions!$C$38 -> 3 | D8: =D7*Assumptions!$C$39 -> 5.1 | E8: =E7*Assumptions!$C$40 -> 6 | F8: =F7*Assumptions!$C$40 -> 6 | G8: =G7*Assumptions!$C$40 -> 6
B9: MD revenue | C9: =C8*Assumptions!$C$34 -> 36000 | D9: =D8*Assumptions!$C$34 -> 61200 | E9: =E8*Assumptions!$C$34 -> 72000 | F9: =F8*Assumptions!$C$34 -> 72000 | G9: =G8*Assumptions!$C$34 -> 72000
B10: MD gross profit | C10: =C9*Assumptions!$C$35 -> 25200 | D10: =D9*Assumptions!$C$35 -> 42840 | E10: =E9*Assumptions!$C$35 -> 50400 | F10: =F9*Assumptions!$C$35 -> 50400 | G10: =G9*Assumptions!$C$35 -> 50400
B13: MD CONVERSION: MID
C14: Y1 | D14: Y2 | E14: Y3 | F14: Y4 | G14: Y5
B15: Steady-state target clients | C15: =Assumptions!$C$33*Assumptions!$C$45 -> 12 | D15: =Assumptions!$C$33*Assumptions!$C$45 -> 12 | E15: =Assumptions!$C$33*Assumptions!$C$45 -> 12 | F15: =Assumptions!$C$33*Assumptions!$C$45 -> 12 | G15: =Assumptions!$C$33*Assumptions!$C$45 -> 12
B16: Active clients (avg over year) | C16: =C15*Assumptions!$C$38 -> 6 | D16: =D15*Assumptions!$C$39 -> 10.2 | E16: =E15*Assumptions!$C$40 -> 12 | F16: =F15*Assumptions!$C$40 -> 12 | G16: =G15*Assumptions!$C$40 -> 12
B17: MD revenue | C17: =C16*Assumptions!$C$34 -> 72000 | D17: =D16*Assumptions!$C$34 -> 122400 | E17: =E16*Assumptions!$C$34 -> 144000 | F17: =F16*Assumptions!$C$34 -> 144000 | G17: =G16*Assumptions!$C$34 -> 144000
B18: MD gross profit | C18: =C17*Assumptions!$C$35 -> 50400 | D18: =D17*Assumptions!$C$35 -> 85680 | E18: =E17*Assumptions!$C$35 -> 100800 | F18: =F17*Assumptions!$C$35 -> 100800 | G18: =G17*Assumptions!$C$35 -> 100800
B21: MD CONVERSION: HIGH
C22: Y1 | D22: Y2 | E22: Y3 | F22: Y4 | G22: Y5
B23: Steady-state target clients | C23: =Assumptions!$C$33*Assumptions!$C$46 -> 18 | D23: =Assumptions!$C$33*Assumptions!$C$46 -> 18 | E23: =Assumptions!$C$33*Assumptions!$C$46 -> 18 | F23: =Assumptions!$C$33*Assumptions!$C$46 -> 18 | G23: =Assumptions!$C$33*Assumptions!$C$46 -> 18
B24: Active clients (avg over year) | C24: =C23*Assumptions!$C$38 -> 9 | D24: =D23*Assumptions!$C$39 -> 15.3 | E24: =E23*Assumptions!$C$40 -> 18 | F24: =F23*Assumptions!$C$40 -> 18 | G24: =G23*Assumptions!$C$40 -> 18
B25: MD revenue | C25: =C24*Assumptions!$C$34 -> 108000 | D25: =D24*Assumptions!$C$34 -> 183600 | E25: =E24*Assumptions!$C$34 -> 216000 | F25: =F24*Assumptions!$C$34 -> 216000 | G25: =G24*Assumptions!$C$34 -> 216000
B26: MD gross profit | C26: =C25*Assumptions!$C$35 -> 75600 | D26: =D25*Assumptions!$C$35 -> 128520 | E26: =E25*Assumptions!$C$35 -> 151200 | F26: =F25*Assumptions!$C$35 -> 151200 | G26: =G25*Assumptions!$C$35 -> 151200
B29: MD CONVERSION: STRETCH
C30: Y1 | D30: Y2 | E30: Y3 | F30: Y4 | G30: Y5
B31: Steady-state target clients | C31: =Assumptions!$C$33*Assumptions!$C$47 -> 24 | D31: =Assumptions!$C$33*Assumptions!$C$47 -> 24 | E31: =Assumptions!$C$33*Assumptions!$C$47 -> 24 | F31: =Assumptions!$C$33*Assumptions!$C$47 -> 24 | G31: =Assumptions!$C$33*Assumptions!$C$47 -> 24
B32: Active clients (avg over year) | C32: =C31*Assumptions!$C$38 -> 12 | D32: =D31*Assumptions!$C$39 -> 20.4 | E32: =E31*Assumptions!$C$40 -> 24 | F32: =F31*Assumptions!$C$40 -> 24 | G32: =G31*Assumptions!$C$40 -> 24
B33: MD revenue | C33: =C32*Assumptions!$C$34 -> 144000 | D33: =D32*Assumptions!$C$34 -> 244800 | E33: =E32*Assumptions!$C$34 -> 288000 | F33: =F32*Assumptions!$C$34 -> 288000 | G33: =G32*Assumptions!$C$34 -> 288000
B34: MD gross profit | C34: =C33*Assumptions!$C$35 -> 100800 | D34: =D33*Assumptions!$C$35 -> 171360 | E34: =E33*Assumptions!$C$35 -> 201600 | F34: =F33*Assumptions!$C$35 -> 201600 | G34: =G33*Assumptions!$C$35 -> 201600

Sheet Combined_Returns
B2: Combined Owner Returns
B3: Print operating cash flow + MD cross-sell gross profit, less debt service. Year 0 = equity outflow at close.
B5: PRINT DOWN + MD LOW
C6: Y0 | D6: Y1 | E6: Y2 | F6: Y3 | G6: Y4 | H6: Y5 | I6: 5-yr Cum.
B7: Print operating cash flow | C7: 0 | D7: =Print_PnL!D12 -> 9827.252 | E7: =Print_PnL!E12 -> 2550.8369 | F7: =Print_PnL!F12 -> -4320.8811 | G7: =Print_PnL!G12 -> -10809.159 | H7: =Print_PnL!H12 -> -16934.165 | I7: =SUM(D7:H7) -> -19686.116
B8: MD cross-sell gross profit | C8: 0 | D8: =MD_CrossSell!C10 -> 25200 | E8: =MD_CrossSell!D10 -> 42840 | F8: =MD_CrossSell!E10 -> 50400 | G8: =MD_CrossSell!F10 -> 50400 | H8: =MD_CrossSell!G10 -> 50400 | I8: =SUM(D8:H8) -> 219240
B9: Debt service | C9: 0 | D9: =-Deal_Structure!$C$27 -> -63787.685 | E9: =-Deal_Structure!$D$27 -> -63787.685 | F9: =-Deal_Structure!$E$27 -> -63787.685 | G9: =-Deal_Structure!$F$27 -> -48545.619 | H9: =-Deal_Structure!$G$27 -> -48545.619 | I9: =SUM(D9:H9) -> -288454.29
B10: Buyer equity at close | C10: =-Deal_Structure!$C$11 -> -105000 | D10: 0 | E10: 0 | F10: 0 | G10: 0 | H10: 0 | I10: =C10 -> -105000
B11: Net cash flow to owner | C11: =SUM(C7:C10) -> -105000 | D11: =SUM(D7:D10) -> -28760.433 | E11: =SUM(E7:E10) -> -18396.849 | F11: =SUM(F7:F10) -> -17708.567 | G11: =SUM(G7:G10) -> -8954.7777 | H11: =SUM(H7:H10) -> -15079.784 | I11: =SUM(C11:H11) -> -193900.41
B12: Cumulative cash | C12: =C11 -> -105000 | D12: =C12+D11 -> -133760.43 | E12: =D12+E11 -> -152157.28 | F12: =E12+F11 -> -169865.85 | G12: =F12+G11 -> -178820.63 | H12: =G12+H11 -> -193900.41
B13: 5-year IRR (on equity) | C13: =IFERROR(IRR(C11:H11),"NM") -> NM
B14: 5-yr cash-on-cash multiple | C14: =IFERROR(SUM(D11:H11)/(-C10),"NM") -> -0.84667057
B17: PRINT BASE + MD LOW
C18: Y0 | D18: Y1 | E18: Y2 | F18: Y3 | G18: Y4 | H18: Y5 | I18: 5-yr Cum.
B19: Print operating cash flow | C19: 0 | D19: =Print_PnL!D22 -> 68030.417 | E19: =Print_PnL!E22 -> 72159.548 | F19: =Print_PnL!F22 -> 76378.347 | G19: =Print_PnL!G22 -> 80688.678 | H19: =Print_PnL!H22 -> 85092.443 | I19: =SUM(D19:H19) -> 382349.43
B20: MD cross-sell gross profit | C20: 0 | D20: =MD_CrossSell!C10 -> 25200 | E20: =MD_CrossSell!D10 -> 42840 | F20: =MD_CrossSell!E10 -> 50400 | G20: =MD_CrossSell!F10 -> 50400 | H20: =MD_CrossSell!G10 -> 50400 | I20: =SUM(D20:H20) -> 219240
B21: Debt service | C21: 0 | D21: =-Deal_Structure!$C$27 -> -63787.685 | E21: =-Deal_Structure!$D$27 -> -63787.685 | F21: =-Deal_Structure!$E$27 -> -63787.685 | G21: =-Deal_Structure!$F$27 -> -48545.619 | H21: =-Deal_Structure!$G$27 -> -48545.619 | I21: =SUM(D21:H21) -> -288454.29
B22: Buyer equity at close | C22: =-Deal_Structure!$C$11 -> -105000 | D22: 0 | E22: 0 | F22: 0 | G22: 0 | H22: 0 | I22: =C22 -> -105000
B23: Net cash flow to owner | C23: =SUM(C19:C22) -> -105000 | D23: =SUM(D19:D22) -> 29442.732 | E23: =SUM(E19:E22) -> 51211.863 | F23: =SUM(F19:F22) -> 62990.662 | G23: =SUM(G19:G22) -> 82543.059 | H23: =SUM(H19:H22) -> 86946.824 | I23: =SUM(C23:H23) -> 208135.14
B24: Cumulative cash | C24: =C23 -> -105000 | D24: =C24+D23 -> -75557.268 | E24: =D24+E23 -> -24345.406 | F24: =E24+F23 -> 38645.256 | G24: =F24+G23 -> 121188.31 | H24: =G24+H23 -> 208135.14
B25: 5-year IRR (on equity) | C25: =IFERROR(IRR(C23:H23),"NM") -> 0.41280167
B26: 5-yr cash-on-cash multiple | C26: =IFERROR(SUM(D23:H23)/(-C22),"NM") -> 2.9822394
B29: PRINT BASE + MD MID
C30: Y0 | D30: Y1 | E30: Y2 | F30: Y3 | G30: Y4 | H30: Y5 | I30: 5-yr Cum.
B31: Print operating cash flow | C31: 0 | D31: =Print_PnL!D22 -> 68030.417 | E31: =Print_PnL!E22 -> 72159.548 | F31: =Print_PnL!F22 -> 76378.347 | G31: =Print_PnL!G22 -> 80688.678 | H31: =Print_PnL!H22 -> 85092.443 | I31: =SUM(D31:H31) -> 382349.43
B32: MD cross-sell gross profit | C32: 0 | D32: =MD_CrossSell!C18 -> 50400 | E32: =MD_CrossSell!D18 -> 85680 | F32: =MD_CrossSell!E18 -> 100800 | G32: =MD_CrossSell!F18 -> 100800 | H32: =MD_CrossSell!G18 -> 100800 | I32: =SUM(D32:H32) -> 438480
B33: Debt service | C33: 0 | D33: =-Deal_Structure!$C$27 -> -63787.685 | E33: =-Deal_Structure!$D$27 -> -63787.685 | F33: =-Deal_Structure!$E$27 -> -63787.685 | G33: =-Deal_Structure!$F$27 -> -48545.619 | H33: =-Deal_Structure!$G$27 -> -48545.619 | I33: =SUM(D33:H33) -> -288454.29
B34: Buyer equity at close | C34: =-Deal_Structure!$C$11 -> -105000 | D34: 0 | E34: 0 | F34: 0 | G34: 0 | H34: 0 | I34: =C34 -> -105000
B35: Net cash flow to owner | C35: =SUM(C31:C34) -> -105000 | D35: =SUM(D31:D34) -> 54642.732 | E35: =SUM(E31:E34) -> 94051.863 | F35: =SUM(F31:F34) -> 113390.66 | G35: =SUM(G31:G34) -> 132943.06 | H35: =SUM(H31:H34) -> 137346.82 | I35: =SUM(C35:H35) -> 427375.14
B36: Cumulative cash | C36: =C35 -> -105000 | D36: =C36+D35 -> -50357.268 | E36: =D36+E35 -> 43694.594 | F36: =E36+F35 -> 157085.26 | G36: =F36+G35 -> 290028.31 | H36: =G36+H35 -> 427375.14
B37: 5-year IRR (on equity) | C37: =IFERROR(IRR(C35:H35),"NM") -> 0.75438932
B38: 5-yr cash-on-cash multiple | C38: =IFERROR(SUM(D35:H35)/(-C34),"NM") -> 5.0702394
B41: PRINT BASE + MD HIGH
C42: Y0 | D42: Y1 | E42: Y2 | F42: Y3 | G42: Y4 | H42: Y5 | I42: 5-yr Cum.
B43: Print operating cash flow | C43: 0 | D43: =Print_PnL!D22 -> 68030.417 | E43: =Print_PnL!E22 -> 72159.548 | F43: =Print_PnL!F22 -> 76378.347 | G43: =Print_PnL!G22 -> 80688.678 | H43: =Print_PnL!H22 -> 85092.443 | I43: =SUM(D43:H43) -> 382349.43
B44: MD cross-sell gross profit | C44: 0 | D44: =MD_CrossSell!C26 -> 75600 | E44: =MD_CrossSell!D26 -> 128520 | F44: =MD_CrossSell!E26 -> 151200 | G44: =MD_CrossSell!F26 -> 151200 | H44: =MD_CrossSell!G26 -> 151200 | I44: =SUM(D44:H44) -> 657720
B45: Debt service | C45: 0 | D45: =-Deal_Structure!$C$27 -> -63787.685 | E45: =-Deal_Structure!$D$27 -> -63787.685 | F45: =-Deal_Structure!$E$27 -> -63787.685 | G45: =-Deal_Structure!$F$27 -> -48545.619 | H45: =-Deal_Structure!$G$27 -> -48545.619 | I45: =SUM(D45:H45) -> -288454.29
B46: Buyer equity at close | C46: =-Deal_Structure!$C$11 -> -105000 | D46: 0 | E46: 0 | F46: 0 | G46: 0 | H46: 0 | I46: =C46 -> -105000
B47: Net cash flow to owner | C47: =SUM(C43:C46) -> -105000 | D47: =SUM(D43:D46) -> 79842.732 | E47: =SUM(E43:E46) -> 136891.86 | F47: =SUM(F43:F46) -> 163790.66 | G47: =SUM(G43:G46) -> 183343.06 | H47: =SUM(H43:H46) -> 187746.82 | I47: =SUM(C47:H47) -> 646615.14
B48: Cumulative cash | C48: =C47 -> -105000 | D48: =C48+D47 -> -25157.268 | E48: =D48+E47 -> 111734.59 | F48: =E48+F47 -> 275525.26 | G48: =F48+G47 -> 458868.31 | H48: =G48+H47 -> 646615.14
...

Sheet Sensitivity
B2: Sensitivity Analysis
B3: Year 3 owner cash flow under Print Base scenario, varying purchase price (rows) and MD steady-state conversion (columns).
B5: Year 3 Net Cash to Owner ($)
B6: Purchase Price \ MD Conv % | C6: 0.05 | D6: 0.075 | E6: 0.1 | F6: 0.15 | G6: 0.2
B7: 350000 | C7: =Print_PnL!F22+(Assumptions!$C$33*0.05*Assumptions!$C$34*Assumptions!$C$35)-(-PMT(Assumptions!$C$8,Assumptions!$C$9,350000*Assumptions!$C$6))-(-PMT(Assumptions!$C$10,Assumptions!$C$11,350000*Assumptions!$C$7)) -> 70964.122 | D7: =Print_PnL!F22+(Assumptions!$C$33*0.075*Assumptions!$C$34*Assumptions!$C$35)-(-PMT(Assumptions!$C$8,Assumptions!$C$9,350000*Assumptions!$C$6))-(-PMT(Assumptions!$C$10,Assumptions!$C$11,350000*Assumptions!$C$7)) -> 96164.122 | E7: =Print_PnL!F22+(Assumptions!$C$33*0.1*Assumptions!$C$34*Assumptions!$C$35)-(-PMT(Assumptions!$C$8,Assumptions!$C$9,350000*Assumptions!$C$6))-(-PMT(Assumptions!$C$10,Assumptions!$C$11,350000*Assumptions!$C$7)) -> 121364.12 | F7: =Print_PnL!F22+(Assumptions!$C$33*0.15*Assumptions!$C$34*Assumptions!$C$35)-(-PMT(Assumptions!$C$8,Assumptions!$C$9,350000*Assumptions!$C$6))-(-PMT(Assumptions!$C$10,Assumptions!$C$11,350000*Assumptions!$C$7)) -> 171764.12 | G7: =Print_PnL!F22+(Assumptions!$C$33*0.2*Assumptions!$C$34*Assumptions!$C$35)-(-PMT(Assumptions!$C$8,Assumptions!$C$9,350000*Assumptions!$C$6))-(-PMT(Assumptions!$C$10,Assumptions!$C$11,350000*Assumptions!$C$7)) -> 222164.12
B8: 400000 | C8: =Print_PnL!F22+(Assumptions!$C$33*0.05*Assumptions!$C$34*Assumptions!$C$35)-(-PMT(Assumptions!$C$8,Assumptions!$C$9,400000*Assumptions!$C$6))-(-PMT(Assumptions!$C$10,Assumptions!$C$11,400000*Assumptions!$C$7)) -> 62990.662 | D8: =Print_PnL!F22+(Assumptions!$C$33*0.075*Assumptions!$C$34*Assumptions!$C$35)-(-PMT(Assumptions!$C$8,Assumptions!$C$9,400000*Assumptions!$C$6))-(-PMT(Assumptions!$C$10,Assumptions!$C$11,400000*Assumptions!$C$7)) -> 88190.662 | E8: =Print_PnL!F22+(Assumptions!$C$33*0.1*Assumptions!$C$34*Assumptions!$C$35)-(-PMT(Assumptions!$C$8,Assumptions!$C$9,400000*Assumptions!$C$6))-(-PMT(Assumptions!$C$10,Assumptions!$C$11,400000*Assumptions!$C$7)) -> 113390.66 | F8: =Print_PnL!F22+(Assumptions!$C$33*0.15*Assumptions!$C$34*Assumptions!$C$35)-(-PMT(Assumptions!$C$8,Assumptions!$C$9,400000*Assumptions!$C$6))-(-PMT(Assumptions!$C$10,Assumptions!$C$11,400000*Assumptions!$C$7)) -> 163790.66 | G8: =Print_PnL!F22+(Assumptions!$C$33*0.2*Assumptions!$C$34*Assumptions!$C$35)-(-PMT(Assumptions!$C$8,Assumptions!$C$9,400000*Assumptions!$C$6))-(-PMT(Assumptions!$C$10,Assumptions!$C$11,400000*Assumptions!$C$7)) -> 214190.66
B9: 450000 | C9: =Print_PnL!F22+(Assumptions!$C$33*0.05*Assumptions!$C$34*Assumptions!$C$35)-(-PMT(Assumptions!$C$8,Assumptions!$C$9,450000*Assumptions!$C$6))-(-PMT(Assumptions!$C$10,Assumptions!$C$11,450000*Assumptions!$C$7)) -> 55017.201 | D9: =Print_PnL!F22+(Assumptions!$C$33*0.075*Assumptions!$C$34*Assumptions!$C$35)-(-PMT(Assumptions!$C$8,Assumptions!$C$9,450000*Assumptions!$C$6))-(-PMT(Assumptions!$C$10,Assumptions!$C$11,450000*Assumptions!$C$7)) -> 80217.201 | E9: =Print_PnL!F22+(Assumptions!$C$33*0.1*Assumptions!$C$34*Assumptions!$C$35)-(-PMT(Assumptions!$C$8,Assumptions!$C$9,450000*Assumptions!$C$6))-(-PMT(Assumptions!$C$10,Assumptions!$C$11,450000*Assumptions!$C$7)) -> 105417.2 | F9: =Print_PnL!F22+(Assumptions!$C$33*0.15*Assumptions!$C$34*Assumptions!$C$35)-(-PMT(Assumptions!$C$8,Assumptions!$C$9,450000*Assumptions!$C$6))-(-PMT(Assumptions!$C$10,Assumptions!$C$11,450000*Assumptions!$C$7)) -> 155817.2 | G9: =Print_PnL!F22+(Assumptions!$C$33*0.2*Assumptions!$C$34*Assumptions!$C$35)-(-PMT(Assumptions!$C$8,Assumptions!$C$9,450000*Assumptions!$C$6))-(-PMT(Assumptions!$C$10,Assumptions!$C$11,450000*Assumptions!$C$7)) -> 206217.2
B10: 500000 | C10: =Print_PnL!F22+(Assumptions!$C$33*0.05*Assumptions!$C$34*Assumptions!$C$35)-(-PMT(Assumptions!$C$8,Assumptions!$C$9,500000*Assumptions!$C$6))-(-PMT(Assumptions!$C$10,Assumptions!$C$11,500000*Assumptions!$C$7)) -> 47043.74 | D10: =Print_PnL!F22+(Assumptions!$C$33*0.075*Assumptions!$C$34*Assumptions!$C$35)-(-PMT(Assumptions!$C$8,Assumptions!$C$9,500000*Assumptions!$C$6))-(-PMT(Assumptions!$C$10,Assumptions!$C$11,500000*Assumptions!$C$7)) -> 72243.74 | E10: =Print_PnL!F22+(Assumptions!$C$33*0.1*Assumptions!$C$34*Assumptions!$C$35)-(-PMT(Assumptions!$C$8,Assumptions!$C$9,500000*Assumptions!$C$6))-(-PMT(Assumptions!$C$10,Assumptions!$C$11,500000*Assumptions!$C$7)) -> 97443.74 | F10: =Print_PnL!F22+(Assumptions!$C$33*0.15*Assumptions!$C$34*Assumptions!$C$35)-(-PMT(Assumptions!$C$8,Assumptions!$C$9,500000*Assumptions!$C$6))-(-PMT(Assumptions!$C$10,Assumptions!$C$11,500000*Assumptions!$C$7)) -> 147843.74 | G10: =Print_PnL!F22+(Assumptions!$C$33*0.2*Assumptions!$C$34*Assumptions!$C$35)-(-PMT(Assumptions!$C$8,Assumptions!$C$9,500000*Assumptions!$C$6))-(-PMT(Assumptions!$C$10,Assumptions!$C$11,500000*Assumptions!$C$7)) -> 198243.74
B11: 550000 | C11: =Print_PnL!F22+(Assumptions!$C$33*0.05*Assumptions!$C$34*Assumptions!$C$35)-(-PMT(Assumptions!$C$8,Assumptions!$C$9,550000*Assumptions!$C$6))-(-PMT(Assumptions!$C$10,Assumptions!$C$11,550000*Assumptions!$C$7)) -> 39070.279 | D11: =Print_PnL!F22+(Assumptions!$C$33*0.075*Assumptions!$C$34*Assumptions!$C$35)-(-PMT(Assumptions!$C$8,Assumptions!$C$9,550000*Assumptions!$C$6))-(-PMT(Assumptions!$C$10,Assumptions!$C$11,550000*Assumptions!$C$7)) -> 64270.279 | E11: =Print_PnL!F22+(Assumptions!$C$33*0.1*Assumptions!$C$34*Assumptions!$C$35)-(-PMT(Assumptions!$C$8,Assumptions!$C$9,550000*Assumptions!$C$6))-(-PMT(Assumptions!$C$10,Assumptions!$C$11,550000*Assumptions!$C$7)) -> 89470.279 | F11: =Print_PnL!F22+(Assumptions!$C$33*0.15*Assumptions!$C$34*Assumptions!$C$35)-(-PMT(Assumptions!$C$8,Assumptions!$C$9,550000*Assumptions!$C$6))-(-PMT(Assumptions!$C$10,Assumptions!$C$11,550000*Assumptions!$C$7)) -> 139870.28 | G11: =Print_PnL!F22+(Assumptions!$C$33*0.2*Assumptions!$C$34*Assumptions!$C$35)-(-PMT(Assumptions!$C$8,Assumptions!$C$9,550000*Assumptions!$C$6))-(-PMT(Assumptions!$C$10,Assumptions!$C$11,550000*Assumptions!$C$7)) -> 190270.28
B14: READ:
B15: Negative cells = the base print scenario does not service debt + operator at this price/conversion combo.
B16: Positive cells > $50K = deal generates real owner cash beyond debt service.
B17: Use this view to set walk-away price given assumed MD conversion.
